<?xml version="1.0"?>
<robot name="rbrobout">

  <!-- Base Footprint -->
  <link name="rbrobout_base_footprint">
    <visual>
      <origin rpy="0 0 0" xyz="0 0 0"/>
      <geometry>
        <box size="0.001 0.001 0.001"/>
      </geometry>
    </visual>
  </link>

  <joint name="rbrobout_base_footprint_joint" type="fixed">
    <origin rpy="0 0 0" xyz="0 0 0.127"/>
    <parent link="rbrobout_base_footprint"/>
    <child link="rbrobout_base_link"/>
  </joint>

  <!-- Base Link -->
  <link name="rbrobout_base_link">
    <inertial>
      <mass value="200.0"/>
      <origin xyz="0 0 0"/>
      <inertia ixx="1.391" ixy="0.004" ixz="0.0" iyy="6.853" iyz="0.0" izz="6.125"/>
    </inertial>
    <visual>
      <origin rpy="0 0 0" xyz="0 0 0"/>
      <geometry>
        <mesh filename="meshes/bases/robout_chassis.stl"/>
      </geometry>
      <material name="darkgrey">
        <color rgba="0.1 0.1 0.1 1"/>
      </material>
    </visual>
    <collision>
      <origin rpy="0 0 0" xyz="0 0 0"/>
      <geometry>
        <mesh filename="meshes/bases/robout_chassis.stl"/>
      </geometry>
    </collision>
  </link>

  <!-- Wheels -->

  <!-- Front Right -->
  <joint name="rbrobout_front_right_wheel_joint" type="continuous">
    <parent link="rbrobout_base_link"/>
    <child link="rbrobout_front_right_wheel_link"/>
    <origin rpy="1.57 0 0" xyz="0.558 -0.2865 0.0"/>
    <axis xyz="0 0 1"/>
  </joint>

  <link name="rbrobout_front_right_wheel_link">
    <visual>
      <origin rpy="0 0 0" xyz="0 0 0"/>
      <geometry>
        <mesh filename="meshes/wheels/omni_wheel/robout_wheel.stl"/>
      </geometry>
    </visual>
    <collision>
      <origin rpy="0 0 0" xyz="0 0 0"/>
      <geometry>
        <cylinder length="0.128" radius="0.127"/>
      </geometry>
    </collision>
    <inertial>
      <mass value="15"/>
      <origin xyz="0 0 0"/>
      <inertia ixx="0.08096" ixy="0" ixz="0" iyy="0.12096" iyz="0" izz="0.08096"/>
    </inertial>
  </link>

  <!-- Front Left -->
  <joint name="rbrobout_front_left_wheel_joint" type="continuous">
    <parent link="rbrobout_base_link"/>
    <child link="rbrobout_front_left_wheel_link"/>
    <origin rpy="1.57 0 0" xyz="0.558 0.2865 0.0"/>
    <axis xyz="0 0 1"/>
  </joint>

  <link name="rbrobout_front_left_wheel_link">
    <visual>
      <geometry>
        <mesh filename="meshes/wheels/omni_wheel/robout_wheel.stl"/>
      </geometry>
    </visual>
    <collision>
      <geometry>
        <cylinder length="0.128" radius="0.127"/>
      </geometry>
    </collision>
    <inertial>
      <mass value="15"/>
      <origin xyz="0 0 0"/>
      <inertia ixx="0.08096" ixy="0" ixz="0" iyy="0.12096" iyz="0" izz="0.08096"/>
    </inertial>
  </link>

  <!-- Back Left -->
  <joint name="rbrobout_back_left_wheel_joint" type="continuous">
    <parent link="rbrobout_base_link"/>
    <child link="rbrobout_back_left_wheel_link"/>
    <origin rpy="1.57 0 0" xyz="-0.558 0.2865 0.0"/>
    <axis xyz="0 0 1"/>
  </joint>

  <link name="rbrobout_back_left_wheel_link">
    <visual>
      <geometry>
        <mesh filename="meshes/wheels/omni_wheel/robout_wheel.stl"/>
      </geometry>
    </visual>
    <collision>
      <geometry>
        <cylinder length="0.128" radius="0.127"/>
      </geometry>
    </collision>
    <inertial>
      <mass value="15"/>
      <origin xyz="0 0 0"/>
      <inertia ixx="0.08096" ixy="0" ixz="0" iyy="0.12096" iyz="0" izz="0.08096"/>
    </inertial>
  </link>

  <!-- Back Right -->
  <joint name="rbrobout_back_right_wheel_joint" type="continuous">
    <parent link="rbrobout_base_link"/>
    <child link="rbrobout_back_right_wheel_link"/>
    <origin rpy="1.57 0 0" xyz="-0.558 -0.2865 0.0"/>
    <axis xyz="0 0 1"/>
  </joint>

  <link name="rbrobout_back_right_wheel_link">
    <visual>
      <geometry>
        <mesh filename="meshes/wheels/omni_wheel/robout_wheel.stl"/>
      </geometry>
    </visual>
    <collision>
      <geometry>
        <cylinder length="0.128" radius="0.127"/>
      </geometry>
    </collision>
    <inertial>
      <mass value="15"/>
      <origin xyz="0 0 0"/>
      <inertia ixx="0.08096" ixy="0" ixz="0" iyy="0.12096" iyz="0" izz="0.08096"/>
    </inertial>
  </link>

  <!-- Sensors -->
  
  <!-- imu -->
  <joint name="rbrobout_imu_joint" type="fixed">
    <axis xyz="1 0 0"/>
    <origin xyz="0.242 -0.053 -0.028" rpy="0 0 0" />
    <parent link="rbrobout_base_link"/>
    <child link="rbrobout_imu_link"/>
  </joint>
  
  <link name="rbrobout_imu_link">
    <inertial>
      <origin rpy="0 0 0" xyz="0.0 0 0.01"/>
      <mass value="0.005"/>
      <inertia ixx="8.333333333333334e-10" ixy="0" ixz="0" iyy="8.333333333333334e-10" iyz="0" izz="8.333333333333334e-10"/>
    </inertial>
    <visual>
      <origin rpy="0 0 0" xyz="0 0 0"/>
      <geometry>
        <box size="0.001 0.001 0.001"/>
      </geometry>
    </visual>
  </link>

  <!-- Front Laser -->
  <joint name="rbrobout_front_laser_base_joint" type="fixed">
    <origin rpy="0 0 0.7853981633974483" xyz="0.8 0.366 -0.06"/>
    <parent link="rbrobout_base_link"/>
    <child link="rbrobout_front_laser_base_link"/>
  </joint>
  
  <link name="rbrobout_front_laser_base_link">
    <collision>
      <origin rpy="0 0 0" xyz="0 0 0.075"/>
      <geometry>
        <box size="0.106 0.094 0.152"/>
      </geometry>
    </collision>
    <visual>
      <origin xyz="0 0 0" rpy="0 0 0" />
      <geometry>
        <mesh filename="package://robotnik_sensors/meshes/sick_microscan3.dae"/>
      </geometry>
    </visual>
    <inertial>
      <mass value="1.15"/>
      <origin rpy="0 0 0" xyz="0 0 0.075"/>
      <inertia ixx="0.0033370124999999996" ixy="0" ixz="0" iyy="0.003358383333333333" iyz="0" izz="0.0023828958333333332"/>
    </inertial>
  </link>
  
  <joint name="rbrobout_front_laser_joint" type="fixed">
    <parent link="rbrobout_front_laser_base_link"/>
    <child link="rbrobout_front_laser_link"/>
    <origin rpy="0 0 0" xyz="0.0 0 0.110"/>
  </joint>
  
  <link name="rbrobout_front_laser_link"/>

  <!-- Rear Laser -->
  <joint name="rbrobout_rear_laser_base_joint" type="fixed">
    <origin  xyz="-0.8 -0.366 -0.06" rpy="0 0 -2.356194490192345"/>
    <parent link="rbrobout_base_link"/>
    <child link="rbrobout_rear_laser_base_link"/>
  </joint>
  
  <link name="rbrobout_rear_laser_base_link">
    <collision>
      <origin rpy="0 0 0" xyz="0 0 0.075"/>
      <geometry>
        <box size="0.106 0.094 0.152"/>
      </geometry>
    </collision>
    <visual>
      <origin rpy="0 0 0" xyz="0 0 0"/>
      <geometry>
        <mesh filename="package://robotnik_sensors/meshes/sick_microscan3.dae"/>
      </geometry>
    </visual>
    <inertial>
      <mass value="1.15"/>
      <origin rpy="0 0 0" xyz="0 0 0.075"/>
      <inertia ixx="0.0033370124999999996" ixy="0" ixz="0" iyy="0.003358383333333333" iyz="0" izz="0.0023828958333333332"/>
    </inertial>
  </link>
  
  <joint name="rbrobout_rear_laser_joint" type="fixed">
    <parent link="rbrobout_rear_laser_base_link"/>
    <child link="rbrobout_rear_laser_link"/>
    <origin xyz="0.0 0 0.110" rpy="0 0 0"/>
  </joint>
  
  <link name="rbrobout_rear_laser_link"/>
  
  <!-- Front rgbd camera -->
  <joint name="rbrobout_front_rgbd_camera_base_joint" type="fixed">
    <origin rpy="0 0 0" xyz="0.835 0  0.1555"/>
    <parent link="rbrobout_base_link"/>
    <child link="rbrobout_front_rgbd_camera_base_link"/>
  </joint>
  
  <link name="rbrobout_front_rgbd_camera_base_link"/>

  <joint name="rbrobout_front_rgbd_camera_joint" type="fixed">
    <parent link="rbrobout_front_rgbd_camera_base_link"/>
    <child link="rbrobout_front_rgbd_camera_link"/>
    <origin rpy="0 0 0" xyz="0.01 0.02 0"/>
    <child link="rbrobout_front_rgbd_camera_link"/>
  </joint>
  
  <link name="rbrobout_front_rgbd_camera_link">
    <visual>
      <origin rpy="1.5707963267948966 0 1.5707963267948966" xyz="0.0149 -0.0175 0"/>
      <geometry>
        <mesh filename="package://robotnik_sensors/meshes/intel_d435.dae"/>
      </geometry>
    </visual>
    <collision>
      <origin rpy="0 0 0" xyz="0 -0.0175 0"/>
      <geometry>
        <box size="0.02505 0.09 0.025"/>
      </geometry>
    </collision>
    <inertial>
      <origin rpy="0 0 0" xyz="0.0025 -0.015 0.0"/>
      <mass value="0.1"/>
      <inertia ixx="7.270833333333333e-05" ixy="0" ixz="0" iyy="1.041666666666667e-05" iyz="0" izz="7.270833333333333e-05"/>
    </inertial>
  </link>

  <joint name="rbrobout_front_rgbd_camera_depth_joint" type="fixed">
    <origin rpy="0 0 0" xyz="0 0 0"/>
    <parent link="rbrobout_front_rgbd_camera_link"/>
    <child link="rbrobout_front_rgbd_camera_depth_frame"/>
  </joint>
  
  <link name="rbrobout_front_rgbd_camera_depth_frame"/>
  
  <joint name="rbrobout_front_rgbd_camera_depth_optical_joint" type="fixed">
    <origin rpy="-1.5707963267948966 0 -1.5707963267948966" xyz="0 0 0"/>
    <parent link="rbrobout_front_rgbd_camera_depth_frame"/>
    <child link="rbrobout_front_rgbd_camera_depth_optical_frame"/>
  </joint>
  
  <link name="rbrobout_front_rgbd_camera_depth_optical_frame"/>

  <joint name="rbrobout_front_rgbd_camera_infra1_joint" type="fixed">
    <origin rpy="0 0 0" xyz="0 0.0 0"/>
    <parent link="rbrobout_front_rgbd_camera_link"/>
    <child link="rbrobout_front_rgbd_camera_infra1_frame"/>
  </joint>
  
  <link name="rbrobout_front_rgbd_camera_infra1_frame"/>
  <joint name="rbrobout_front_rgbd_camera_infra1_optical_joint" type="fixed">
    <origin rpy="-1.5707963267948966 0 -1.5707963267948966" xyz="0 0 0"/>
    <parent link="rbrobout_front_rgbd_camera_infra1_frame"/>
    <child link="rbrobout_front_rgbd_camera_infra1_optical_frame"/>
  </joint>
  
  <link name="rbrobout_front_rgbd_camera_infra1_optical_frame"/>
  <joint name="rbrobout_front_rgbd_camera_infra2_joint" type="fixed">
    <origin rpy="0 0 0" xyz="0 -0.05 0"/>
    <parent link="rbrobout_front_rgbd_camera_link"/>
    <child link="rbrobout_front_rgbd_camera_infra2_frame"/>
  </joint>
  
  <link name="rbrobout_front_rgbd_camera_infra2_frame"/>
  <joint name="rbrobout_front_rgbd_camera_infra2_optical_joint" type="fixed">
    <origin rpy="-1.5707963267948966 0 -1.5707963267948966" xyz="0 0 0"/>
    <parent link="rbrobout_front_rgbd_camera_infra2_frame"/>
    <child link="rbrobout_front_rgbd_camera_infra2_optical_frame"/>
  </joint>
  
  <link name="rbrobout_front_rgbd_camera_infra2_optical_frame"/>
  <joint name="rbrobout_front_rgbd_camera_color_joint" type="fixed">
    <origin rpy="0 0 0" xyz="0 0.015 0"/>
    <parent link="rbrobout_front_rgbd_camera_link"/>
    <child link="rbrobout_front_rgbd_camera_color_frame"/>
  </joint>
  
  <link name="rbrobout_front_rgbd_camera_color_frame"/>
  <joint name="rbrobout_front_rgbd_camera_color_optical_joint" type="fixed">
    <origin rpy="-1.5707963267948966 0 -1.5707963267948966" xyz="0 0 0"/>
    <parent link="rbrobout_front_rgbd_camera_color_frame"/>
    <child link="rbrobout_front_rgbd_camera_color_optical_frame"/>
  </joint>
  
  <link name="rbrobout_front_rgbd_camera_color_optical_frame"/>

  <joint name="rbrobout_rear_rgbd_camera_base_joint" type="fixed">
    <origin rpy="0 3.141592653589793 0" xyz="-0.835 0  0.1555"/>
    <parent link="rbrobout_base_link"/>
    <child link="rbrobout_rear_rgbd_camera_base_link"/>
  </joint>
  
  <link name="rbrobout_rear_rgbd_camera_base_link"/>

  <joint name="rbrobout_rear_rgbd_camera_joint" type="fixed">
    <parent link="rbrobout_rear_rgbd_camera_base_link"/>
    <child link="rbrobout_rear_rgbd_camera_link"/>
    <origin rpy="0 0 0" xyz="0.01 0.02 0"/>
    <child link="rbrobout_rear_rgbd_camera_link"/>
  </joint>
  
  <link name="rbrobout_rear_rgbd_camera_link">
    <visual>
      <origin rpy="1.5707963267948966 0 1.5707963267948966" xyz="0.0149 -0.0175 0"/>
      <geometry>
        <mesh filename="package://robotnik_sensors/meshes/intel_d435.dae"/>
      </geometry>
    </visual>
    <collision>
      <origin rpy="0 0 0" xyz="0 -0.0175 0"/>
      <geometry>
        <box size="0.02505 0.09 0.025"/>
      </geometry>
    </collision>
    <inertial>
      <origin rpy="0 0 0" xyz="0.0025 -0.015 0.0"/>
      <mass value="0.1"/>
      <inertia ixx="7.270833333333333e-05" ixy="0" ixz="0" iyy="1.041666666666667e-05" iyz="0" izz="7.270833333333333e-05"/>
    </inertial>
  </link>

  <joint name="rbrobout_rear_rgbd_camera_depth_joint" type="fixed">
    <origin rpy="0 0 0" xyz="0 0 0"/>
    <parent link="rbrobout_rear_rgbd_camera_link"/>
    <child link="rbrobout_rear_rgbd_camera_depth_frame"/>
  </joint>
  
  <link name="rbrobout_rear_rgbd_camera_depth_frame"/>
  <joint name="rbrobout_rear_rgbd_camera_depth_optical_joint" type="fixed">
    <origin rpy="-1.5707963267948966 0 -1.5707963267948966" xyz="0 0 0"/>
    <parent link="rbrobout_rear_rgbd_camera_depth_frame"/>
    <child link="rbrobout_rear_rgbd_camera_depth_optical_frame"/>
  </joint>
  
  <link name="rbrobout_rear_rgbd_camera_depth_optical_frame"/>
  <joint name="rbrobout_rear_rgbd_camera_infra1_joint" type="fixed">
    <origin rpy="0 0 0" xyz="0 0.0 0"/>
    <parent link="rbrobout_rear_rgbd_camera_link"/>
    <child link="rbrobout_rear_rgbd_camera_infra1_frame"/>
  </joint>
  
  <link name="rbrobout_rear_rgbd_camera_infra1_frame"/>
  <joint name="rbrobout_rear_rgbd_camera_infra1_optical_joint" type="fixed">
    <origin rpy="-1.5707963267948966 0 -1.5707963267948966" xyz="0 0 0"/>
    <parent link="rbrobout_rear_rgbd_camera_infra1_frame"/>
    <child link="rbrobout_rear_rgbd_camera_infra1_optical_frame"/>
  </joint>
  
  <link name="rbrobout_rear_rgbd_camera_infra1_optical_frame"/>
  <joint name="rbrobout_rear_rgbd_camera_infra2_joint" type="fixed">
    <origin rpy="0 0 0" xyz="0 -0.05 0"/>
    <parent link="rbrobout_rear_rgbd_camera_link"/>
    <child link="rbrobout_rear_rgbd_camera_infra2_frame"/>
  </joint>
  
  <link name="rbrobout_rear_rgbd_camera_infra2_frame"/>
  <joint name="rbrobout_rear_rgbd_camera_infra2_optical_joint" type="fixed">
    <origin rpy="-1.5707963267948966 0 -1.5707963267948966" xyz="0 0 0"/>
    <parent link="rbrobout_rear_rgbd_camera_infra2_frame"/>
    <child link="rbrobout_rear_rgbd_camera_infra2_optical_frame"/>
  </joint>
  
  <link name="rbrobout_rear_rgbd_camera_infra2_optical_frame"/>
  <joint name="rbrobout_rear_rgbd_camera_color_joint" type="fixed">
    <origin rpy="0 0 0" xyz="0 0.015 0"/>
    <parent link="rbrobout_rear_rgbd_camera_link"/>
    <child link="rbrobout_rear_rgbd_camera_color_frame"/>
  </joint>
  
  <link name="rbrobout_rear_rgbd_camera_color_frame"/>
  <joint name="rbrobout_rear_rgbd_camera_color_optical_joint" type="fixed">
    <origin rpy="-1.5707963267948966 0 -1.5707963267948966" xyz="0 0 0"/>
    <parent link="rbrobout_rear_rgbd_camera_color_frame"/>
    <child link="rbrobout_rear_rgbd_camera_color_optical_frame"/>
  </joint>
  
  <link name="rbrobout_rear_rgbd_camera_color_optical_frame"/>
  
 </robot>

