<?xml version="1.0" ?>
<robot name="summit_xl">

  <!-- Base footprint -->
  <link name="robot_base_footprint">
    <visual>
      <origin rpy="0 0 0" xyz="0 0 0"/>
      <geometry>
        <box size="0.001 0.001 0.001"/>
      </geometry>
    </visual>
  </link>
  
  <joint name="robot_base_footprint_joint" type="fixed">
    <origin rpy="0 0 0" xyz="0 0 0.1175"/>
    <parent link="robot_base_footprint"/>
    <child link="robot_base_link"/>
  </joint>
  
  <!-- Base link -->
  <link name="robot_base_link">
    <inertial>
      <mass value="50.0"/>
      <origin xyz="0 0 0"/>
      <inertia ixx="1.391" ixy="0.004" ixz="0.0" iyy="6.853" iyz="0.0" izz="6.125"/>
    </inertial>
    <visual>
      <origin rpy="0 0 0" xyz="0 0 0"/>
      <geometry>
        <mesh filename="meshes/bases/rbwatcher_body.dae"/>
      </geometry>
    </visual>
    <collision>
      <origin rpy="0 0 0 " xyz="0 0 0"/>
      <geometry>
        <mesh filename="meshes/bases/rbwatcher_body.stl"/>
      </geometry>
    </collision>
  </link>
  
  <!-- Docking -->
  <joint name="robot_base_docking_joint" type="fixed">
    <origin rpy="0 0 0 " xyz="0.29378 0.0 0.07321"/>
    <parent link="robot_base_link"/>
    <child link="robot_base_docking_contact_link"/>
  </joint>

  <link name="robot_base_docking_contact_link"/>

  <!-- ****** -->  
  <!-- WHEELS -->
  <!-- ****** -->
  
  <!-- Front Right -->
  <joint name="robot_front_right_wheel_joint" type="continuous">
    <origin xyz="0.22795 -0.155 0.0" rpy="0 0 0" />
    <parent link="robot_base_link"/>
    <child link="robot_front_right_wheel"/>
    <axis rpy="0 0 0" xyz="0 1 0"/>
  </joint>
  
  <link name="robot_front_right_wheel">
    <visual>
      <origin rpy="0 0 0" xyz="0 0 0"/>
      <geometry>
        <mesh filename="meshes/wheels/rubber_wheel/rubber_wheel_v2_right.dae"/>
      </geometry>
    </visual>
    <collision>
      <origin rpy="0 0 0" xyz="0 0 0"/>
      <geometry>
        <mesh filename="meshes/wheels/rubber_wheel/rubber_wheel_v2_right.stl"/>
      </geometry>
    </collision>
    <inertial>
      <mass value="4"/>
      <origin xyz="0 0 0"/>
      <inertia ixx="0.02052758333333333" ixy="0" ixz="0" iyy="0.027612499999999998" iyz="0" izz="0.02052758333333333"/>
    </inertial>
  </link>
  
  <!-- Front Left -->
  <joint name="robot_front_left_wheel_joint" type="continuous">
    <origin xyz="0.22795 0.155 0.0" rpy="0 0 0" />
    <parent link="robot_base_link"/>
    <child link="robot_front_left_wheel"/>
    <axis rpy="0 0 0" xyz="0 1 0"/>
  </joint>
  
  <link name="robot_front_left_wheel">
    <visual>
      <origin rpy="0 0 0" xyz="0 0 0"/>
      <geometry>
        <mesh filename="meshes/wheels/rubber_wheel/rubber_wheel_v2_left.dae"/>
      </geometry>
    </visual>
    <collision>
      <origin rpy="0 0 0" xyz="0 0 0"/>
      <geometry>
        <mesh filename="meshes/wheels/rubber_wheel/rubber_wheel_v2_left.stl"/>
      </geometry>
    </collision>
    <inertial>
      <mass value="4"/>
      <origin xyz="0 0 0"/>
      <inertia ixx="0.02052758333333333" ixy="0" ixz="0" iyy="0.027612499999999998" iyz="0" izz="0.02052758333333333"/>
    </inertial>
  </link>

  <!-- Back Left -->
  <joint name="robot_back_left_wheel_joint" type="continuous">
    <origin xyz="-0.22795 0.155 0.0" rpy="0 0 0" />
    <parent link="robot_base_link"/>
    <child link="robot_back_left_wheel"/>
    <axis rpy="0 0 0" xyz="0 1 0"/>
  </joint>
  
  <link name="robot_back_left_wheel">
    <visual>
      <origin rpy="0 0 0" xyz="0 0 0"/>
      <geometry>
        <mesh filename="meshes/wheels/rubber_wheel/rubber_wheel_v2_left.dae"/>
      </geometry>
    </visual>
    <collision>
      <origin rpy="0 0 0" xyz="0 0 0"/>
      <geometry>
        <mesh filename="meshes/wheels/rubber_wheel/rubber_wheel_v2_left.stl"/>
      </geometry>
    </collision>
    <inertial>
      <mass value="4"/>
      <origin xyz="0 0 0"/>
      <inertia ixx="0.02052758333333333" ixy="0" ixz="0" iyy="0.027612499999999998" iyz="0" izz="0.02052758333333333"/>
    </inertial>
  </link>
  
  <!--Back Right -->
  <joint name="robot_back_right_wheel_joint" type="continuous">
    <origin xyz="-0.22795 -0.155 0.0" rpy="0 0 0"/>
    <parent link="robot_base_link"/>
    <child link="robot_back_right_wheel"/>
    <axis rpy="0 0 0" xyz="0 1 0"/>
  </joint>
  
  <link name="robot_back_right_wheel">
    <visual>
      <origin rpy="0 0 0" xyz="0 0 0"/>
      <geometry>
        <mesh filename="meshes/wheels/rubber_wheel/rubber_wheel_v2_right.dae"/>
      </geometry>
    </visual>
    <collision>
      <origin rpy="0 0 0" xyz="0 0 0"/>
      <geometry>
        <mesh filename="meshes/wheels/rubber_wheel/rubber_wheel_v2_right.stl"/>
      </geometry>
    </collision>
    <inertial>
      <mass value="4"/>
      <origin xyz="0 0 0"/>
      <inertia ixx="0.02052758333333333" ixy="0" ixz="0" iyy="0.027612499999999998" iyz="0" izz="0.02052758333333333"/>
    </inertial>
  </link>
  
  <joint name="robot_top_structure_joint" type="fixed">
    <axis xyz="0 0 1"/>
    <origin rpy="0 0 0" xyz="-0.17024 0 0.27609"/>
    <parent link="robot_base_link"/>
    <child link="robot_top_structure_link"/>
  </joint>
  
  <!-- Top Structure --> 
  <link name="robot_top_structure_link">
    <visual>
      <origin rpy="0 0 0" xyz="0 0 0"/>
      <geometry>
        <mesh filename="meshes/structures/rbwatcher/rbwatcher_top_structure.dae"/>
      </geometry>
    </visual>
    <collision>
      <origin rpy="0 0 0" xyz="0 0 0"/>
      <geometry>
        <mesh filename="meshes/structures/rbwatcher/rbwatcher_top_structure.stl"/>
      </geometry>
    </collision>
  </link>

<!-- SENSORS -->

  <joint name="robot_imu_joint" type="fixed">
    <axis xyz="1 0 0"/>
    <!--origin xyz="0 0 0.2825"/-->
    <origin rpy="0 0 0" xyz="-0.03534 0.132 0.16109"/>
    <parent link="robot_base_link"/>
    <child link="robot_imu_link"/>
  </joint>
  <link name="robot_imu_link">
    <inertial>
      <origin rpy="0 0 0" xyz="0.0 0 0.01"/>
      <mass value="0.005"/>
      <inertia ixx="8.333333333333334e-10" ixy="0" ixz="0" iyy="8.333333333333334e-10" iyz="0" izz="8.333333333333334e-10"/>
    </inertial>
    <visual>
      <origin rpy="0 0 0" xyz="0 0 0"/>
      <geometry>
        <box size="0.001 0.001 0.001"/>
      </geometry>
    </visual>
    <!--collision>
	        <origin rpy="0 0 0" xyz="0 0 0"/>
	        <geometry>
	          <box size="0.001 0.001 0.001"/>
	        </geometry>
	      </collision-->
  </link>

  <joint name="robot_front_rgbd_camera_base_joint" type="fixed">
    <origin rpy="0 0 0" xyz="0.29881 0.0 0.15243"/>
    <parent link="robot_base_link"/>
    <child link="robot_front_rgbd_camera_base_link"/>
  </joint>
  <link name="robot_front_rgbd_camera_base_link"/>
  <joint name="robot_front_rgbd_camera_joint" type="fixed">
    <parent link="robot_front_rgbd_camera_base_link"/>
    <child link="robot_front_rgbd_camera_link"/>
    <origin rpy="0 0 0" xyz="0.01 0.02 0"/>
    <child link="robot_front_rgbd_camera_link"/>
  </joint>
  <link name="robot_front_rgbd_camera_link">
    <visual>
      <origin rpy="1.5707963267948966 0 1.5707963267948966" xyz="0.0149 -0.0175 0"/>
      <geometry>
        <mesh filename="robotnik_sensors/meshes/intel_d435.dae"/>
      </geometry>
    </visual>
    <collision>
      <origin rpy="0 0 0" xyz="0 -0.0175 0"/>
      <geometry>
        <box size="0.02505 0.09 0.025"/>
      </geometry>
    </collision>
    <inertial>
      <origin rpy="0 0 0" xyz="0.0025 -0.015 0.0"/>
      <mass value="0.1"/>
      <inertia ixx="7.270833333333333e-05" ixy="0" ixz="0" iyy="1.041666666666667e-05" iyz="0" izz="7.270833333333333e-05"/>
    </inertial>
  </link>
  <joint name="robot_front_rgbd_camera_depth_joint" type="fixed">
    <origin rpy="0 0 0" xyz="0 0 0"/>
    <parent link="robot_front_rgbd_camera_link"/>
    <child link="robot_front_rgbd_camera_depth_frame"/>
  </joint>
  <link name="robot_front_rgbd_camera_depth_frame"/>
  <joint name="robot_front_rgbd_camera_depth_optical_joint" type="fixed">
    <origin rpy="-1.5707963267948966 0 -1.5707963267948966" xyz="0 0 0"/>
    <parent link="robot_front_rgbd_camera_depth_frame"/>
    <child link="robot_front_rgbd_camera_depth_optical_frame"/>
  </joint>
  <link name="robot_front_rgbd_camera_depth_optical_frame"/>
  <joint name="robot_front_rgbd_camera_infra1_joint" type="fixed">
    <origin rpy="0 0 0" xyz="0 0.0 0"/>
    <parent link="robot_front_rgbd_camera_link"/>
    <child link="robot_front_rgbd_camera_infra1_frame"/>
  </joint>
  <link name="robot_front_rgbd_camera_infra1_frame"/>
  <joint name="robot_front_rgbd_camera_infra1_optical_joint" type="fixed">
    <origin rpy="-1.5707963267948966 0 -1.5707963267948966" xyz="0 0 0"/>
    <parent link="robot_front_rgbd_camera_infra1_frame"/>
    <child link="robot_front_rgbd_camera_infra1_optical_frame"/>
  </joint>
  <link name="robot_front_rgbd_camera_infra1_optical_frame"/>
  <joint name="robot_front_rgbd_camera_infra2_joint" type="fixed">
    <origin rpy="0 0 0" xyz="0 -0.05 0"/>
    <parent link="robot_front_rgbd_camera_link"/>
    <child link="robot_front_rgbd_camera_infra2_frame"/>
  </joint>
  <link name="robot_front_rgbd_camera_infra2_frame"/>
  <joint name="robot_front_rgbd_camera_infra2_optical_joint" type="fixed">
    <origin rpy="-1.5707963267948966 0 -1.5707963267948966" xyz="0 0 0"/>
    <parent link="robot_front_rgbd_camera_infra2_frame"/>
    <child link="robot_front_rgbd_camera_infra2_optical_frame"/>
  </joint>
  <link name="robot_front_rgbd_camera_infra2_optical_frame"/>
  <joint name="robot_front_rgbd_camera_color_joint" type="fixed">
    <origin rpy="0 0 0" xyz="0 0.015 0"/>
    <parent link="robot_front_rgbd_camera_link"/>
    <child link="robot_front_rgbd_camera_color_frame"/>
  </joint>
  <link name="robot_front_rgbd_camera_color_frame"/>
  <joint name="robot_front_rgbd_camera_color_optical_joint" type="fixed">
    <origin rpy="-1.5707963267948966 0 -1.5707963267948966" xyz="0 0 0"/>
    <parent link="robot_front_rgbd_camera_color_frame"/>
    <child link="robot_front_rgbd_camera_color_optical_frame"/>
  </joint>
  <link name="robot_front_rgbd_camera_color_optical_frame"/>

  <joint name="robot_gps_base_joint" type="fixed">
    <axis xyz="0 1 0"/>
    <origin rpy="0 0 0" xyz="-0.24824 0.095 0.76359"/>
    <parent link="robot_base_link"/>
    <child link="robot_gps_base_link"/>
  </joint>
  <link name="robot_gps_base_link">
    <inertial>
      <origin rpy="0 0 0" xyz="0.0 0 0.015"/>
      <mass value="0.2"/>
      <inertia ixx="0.00012435" ixy="0" ixz="0" iyy="0.00012435" iyz="0" izz="0.00021870000000000003"/>
    </inertial>
    <visual>
      <origin rpy="0 0 0" xyz="0 0 0"/>
      <material name="ublox_gps_color">
        <color rgba="0.5 0.5 0.5 1"/>
      </material>
      <geometry>
        <mesh filename="robotnik_sensors/meshes/antenna_ANN_MB.stl" scale="1.0 1.0 1.0"/>
      </geometry>
    </visual>
    <collision>
      <origin rpy="0 0 0" xyz="0 0 0.01125"/>
      <geometry>
        <box size="0.0607 0.083 0.0225"/>
      </geometry>
    </collision>
  </link>
  <joint name="robot_gps_joint" type="fixed">
    <axis xyz="1 0 0"/>
    <origin xyz="0.0 0.0 0.01125"/>
    <parent link="robot_gps_base_link"/>
    <child link="robot_gps_link"/>
  </joint>
  <link name="robot_gps_link">
	  </link>

  <joint name="robot_top_3d_laser_base_joint" type="fixed">
    <origin rpy="0 0 0" xyz="-0.11924 0.0 0.38609"/>
    <parent link="robot_base_link"/>
    <child link="robot_top_3d_laser_base_link"/>
  </joint>
  <link name="robot_top_3d_laser_base_link">
    <visual>
      <origin rpy="0 0 0" xyz="0 0 0"/>
      <geometry>
        <mesh filename="robotnik_sensors/meshes/rs_helios_16p.stl"/>
      </geometry>
      <material name="black_alu">
        <color rgba="0.9 0.9 0.9 1"/>
      </material>
    </visual>
    <collision>
      <origin rpy="0 0 0" xyz="0 0 0.05"/>
      <geometry>
        <cylinder length="0.1" radius="0.05"/>
      </geometry>
    </collision>
    <inertial>
      <mass value="1.0"/>
      <origin xyz="0 0 0.04135"/>
      <inertia ixx="0.0013104203" ixy="0" ixz="0" iyy="0.0013104203" iyz="0" izz="0.00166334"/>
    </inertial>
  </link>
  <joint name="robot_top_3d_laser_joint" type="fixed">
    <parent link="robot_top_3d_laser_base_link"/>
    <child link="robot_top_3d_laser_link"/>
    <origin rpy="0 0 0" xyz="0.0 0 0.0635"/>
  </joint>
  <link name="robot_top_3d_laser_link"/>

  <joint name="robot_antenna_joint" type="fixed">
    <axis xyz="0 1 0"/>
    <origin rpy="0 0 0" xyz="-0.24124 0.0 0.31109"/>
    <parent link="robot_base_link"/>
    <child link="robot_antenna_base_link"/>
  </joint>
  <link name="robot_antenna_base_link">
    <visual>
      <origin rpy="0 0 0" xyz="0 0 0"/>
      <geometry>
        <mesh filename="meshes/others/antena_wifi_2J7A747Bc.dae"/>
      </geometry>
    </visual>
    <collision>
      <origin rpy="0 0 0" xyz="0 0 0"/>
      <geometry>
        <mesh filename="meshes/others/antena_wifi_2J7A747Bc.stl"/>
      </geometry>
    </collision>
  </link>
  
  <joint name="robot_top_ptz_camera_joint" type="fixed">
    <axis xyz="0 0 1"/>
    <origin rpy="0 0 0" xyz="-0.11808 0 0.55429"/>
    <parent link="robot_base_link"/>
    <child link="robot_top_ptz_camera_base_link"/>
  </joint>
  <link name="robot_top_ptz_camera_base_link">
    <inertial>
      <origin rpy="0 0 0" xyz="0.066 0 0"/>
      <mass value="0.8"/>
      <inertia ixx="0.0029766000000000007" ixy="0" ixz="0" iyy="0.0029766000000000007" iyz="0" izz="0.003630000000000001"/>
    </inertial>
    <visual>
      <origin rpy="0 0 0" xyz="-0.07 -0.07 -0.045"/>
      <material name="grey_color">
        <color rgba="0.1 0.1 0.1 1"/>
      </material>
      <geometry>
        <mesh filename="robotnik_sensors/meshes/link_750_base.stl" scale="0.001 0.001 0.001"/>
      </geometry>
    </visual>
    <collision>
      <origin rpy="0 0 0" xyz="-0.07 -0.07 -0.045"/>
      <geometry>
        <mesh filename="robotnik_sensors/meshes/link_750_base.stl" scale="0.001 0.001 0.001"/>
      </geometry>
    </collision>
  </link>
  <joint name="robot_top_ptz_camera_pan_joint" type="revolute">
    <axis xyz="0 0 1"/>
    <origin rpy="0 0 0" xyz="0.0 0.0 0.0318"/>
    <!-- check the displacement -->
    <parent link="robot_top_ptz_camera_base_link"/>
    <child link="robot_top_ptz_camera_pan_link"/>
    <limit effort="10.0" lower="-3.1416" upper="3.1416" velocity="1.0"/>
    <joint_properties damping="0.1" friction="{ptz_joint_friction}"/>
  </joint>
  <link name="robot_top_ptz_camera_pan_link">
    <inertial>
      <mass value="0.1"/>
      <origin rpy="0 0 0" xyz="0 0 0"/>
      <inertia ixx="0.0002016666666666667" ixy="0" ixz="0" iyy="0.00018416666666666668" iyz="0" izz="0.00018416666666666668"/>
    </inertial>
    <visual>
      <origin rpy="0 0 0" xyz="0 0 0"/>
      <material name="grey_color">
        <color rgba="0.1 0.1 0.1 1"/>
      </material>
      <geometry>
        <mesh filename="robotnik_sensors/meshes/link_750_pan.stl" scale="1.0 1.0 1.0"/>
      </geometry>
    </visual>
    <collision>
      <origin rpy="0 0 0" xyz="0.0 0.0 0"/>
      <geometry>
        <mesh filename="robotnik_sensors/meshes/link_750_pan.stl" scale="1.0 1.0 1.0"/>
      </geometry>
    </collision>
  </link>
  <transmission name="robot_top_ptz_camera_pan_trans">
    <type>transmission_interface/SimpleTransmission</type>
    <joint name="robot_top_ptz_camera_pan_joint">
      <hardwareInterface>hardware_interface/PositionJointInterface</hardwareInterface>
    </joint>
    <actuator name="robot_top_ptz_camerapan_motor">
      <hardwareInterface>hardware_interface/PositionJointInterface</hardwareInterface>
      <mechanicalReduction>1.0</mechanicalReduction>
    </actuator>
  </transmission>
  <joint name="robot_top_ptz_camera_tilt_joint" type="revolute">
    <axis xyz="0 0 1"/>
    <origin rpy="1.5707963267948966 0 0" xyz="0.0 0.0 0.102"/>
    <parent link="robot_top_ptz_camera_pan_link"/>
    <child link="robot_top_ptz_camera_tilt_link"/>
    <limit effort="10.0" lower="-1.5708" upper="1.5708" velocity="1.0"/>
    <joint_properties damping="0.1" friction="{ptz_joint_friction}"/>
  </joint>
  <link name="robot_top_ptz_camera_tilt_link">
    <inertial>
      <mass value="0.1"/>
      <origin rpy="0 0 0" xyz="0 0 0"/>
      <inertia ixx="0.00018416666666666668" ixy="0" ixz="0" iyy="0.00018416666666666668" iyz="0" izz="0.0002016666666666667"/>
    </inertial>
    <visual>
      <origin rpy="1.5707963267948966 0 0" xyz="0 0 0"/>
      <material name="grey_color">
        <color rgba="0.1 0.1 0.1 1"/>
      </material>
      <geometry>
        <mesh filename="robotnik_sensors/meshes/link_750_tilt.stl" scale="1.0 1.0 1.0"/>
      </geometry>
    </visual>
    <collision>
      <origin rpy="1.5707963267948966 0 0" xyz="0.0 0.0 0"/>
      <geometry>
        <mesh filename="robotnik_sensors/meshes/link_750_tilt.stl" scale="1.0 1.0 1.0"/>
      </geometry>
    </collision>
  </link>
  <transmission name="robot_top_ptz_camera_tilt_trans">
    <type>transmission_interface/SimpleTransmission</type>
    <joint name="robot_top_ptz_camera_tilt_joint">
      <hardwareInterface>hardware_interface/PositionJointInterface</hardwareInterface>
    </joint>
    <actuator name="robot_top_ptz_cameratilt_motor">
      <hardwareInterface>hardware_interface/PositionJointInterface</hardwareInterface>
      <mechanicalReduction>1.0</mechanicalReduction>
    </actuator>
  </transmission>
  <joint name="robot_top_ptz_camera_zoom_color_joint" type="prismatic">
    <axis xyz="0 0 1"/>
    <origin rpy="0 0 0" xyz="0.0 0.0 0.0"/>
    <parent link="robot_top_ptz_camera_optical_frame_link"/>
    <child link="robot_top_ptz_camera_zoom_color_link"/>
    <limit effort="10000.0" lower="0" upper="10000" velocity="5"/>
  </joint>
  <link name="robot_top_ptz_camera_zoom_color_link">
    <inertial>
      <mass value="0.00001"/>
      <origin rpy="0 0 0" xyz="0 0 0"/>
      <inertia ixx="1.841666666666667e-08" ixy="0" ixz="0" iyy="1.841666666666667e-08" iyz="0" izz="2.016666666666667e-08"/>
    </inertial>
  </link>
  <transmission name="robot_top_ptz_camera_zoom_color_trans">
    <type>transmission_interface/SimpleTransmission</type>
    <joint name="robot_top_ptz_camera_zoom_color_joint">
      <hardwareInterface>hardware_interface/PositionJointInterface</hardwareInterface>
    </joint>
    <actuator name="robot_top_ptz_camerazoom_motor">
      <hardwareInterface>hardware_interface/PositionJointInterface</hardwareInterface>
      <mechanicalReduction>1</mechanicalReduction>
    </actuator>
  </transmission>
  <joint name="robot_top_ptz_camera_frame_joint" type="fixed">
    <origin rpy="-1.5707963267948966 0 0" xyz="0.05 0.025 0"/>
    <parent link="robot_top_ptz_camera_tilt_link"/>
    <child link="robot_top_ptz_camera_frame_link"/>
  </joint>
  <link name="robot_top_ptz_camera_frame_link">
    <inertial>
      <mass value="0.1"/>
      <origin xyz="0 0 0"/>
      <inertia ixx="0.00018416666666666668" ixy="0" ixz="0" iyy="0.00018416666666666668" iyz="0" izz="0.0002016666666666667"/>
    </inertial>
  </link>
  <!-- Optical frame ${-M_PI/2} -->
  <joint name="robot_top_ptz_camera_optical_joint" type="fixed">
    <origin rpy="-1.5707963267948966 0 -1.5707963267948966" xyz="0.0 0 0"/>
    <parent link="robot_top_ptz_camera_frame_link"/>
    <child link="robot_top_ptz_camera_optical_frame_link"/>
  </joint>
  <link name="robot_top_ptz_camera_optical_frame_link">
    <inertial>
      <mass value="0.1"/>
      <origin xyz="0 0 0"/>
      <inertia ixx="0.00018416666666666668" ixy="0" ixz="0" iyy="0.00018416666666666668" iyz="0" izz="0.0002016666666666667"/>
    </inertial>
  </link>

  <joint name="robot_top_ptz_camera_thermal_frame_joint" type="fixed">
    <origin rpy="-1.5707963267948966 0 0" xyz="0.05 -0.025 0.0"/>
    <parent link="robot_top_ptz_camera_tilt_link"/>
    <child link="robot_top_ptz_camera_thermal_frame_link"/>
  </joint>
  <link name="robot_top_ptz_camera_thermal_frame_link">
    <inertial>
      <mass value="0.1"/>
      <origin xyz="0 0 0"/>
      <inertia ixx="0.00018416666666666668" ixy="0" ixz="0" iyy="0.00018416666666666668" iyz="0" izz="0.0002016666666666667"/>
    </inertial>
  </link>
  <!-- Optical frame ${-M_PI/2} -->
  <joint name="robot_top_ptz_camera_optical_thermal_joint" type="fixed">
    <origin rpy="-1.5707963267948966 0 -1.5707963267948966" xyz="0.0 0 0"/>
    <parent link="robot_top_ptz_camera_thermal_frame_link"/>
    <child link="robot_top_ptz_camera_optical_thermal_frame_link"/>
  </joint>
  <link name="robot_top_ptz_camera_optical_thermal_frame_link">
    <inertial>
      <mass value="0.1"/>
      <origin xyz="0 0 0"/>
      <inertia ixx="0.00018416666666666668" ixy="0" ixz="0" iyy="0.00018416666666666668" iyz="0" izz="0.0002016666666666667"/>
    </inertial>
  </link>
  <joint name="robot_top_ptz_camera_zoom_thermal_joint" type="prismatic">
    <axis xyz="0 0 1"/>
    <origin rpy="0 0 0" xyz="0.0 0.0 0.0"/>
    <parent link="robot_top_ptz_camera_optical_thermal_frame_link"/>
    <child link="robot_top_ptz_camera_zoom_thermal_link"/>
    <limit effort="10000.0" lower="0" upper="10000" velocity="5"/>
  </joint>
  <link name="robot_top_ptz_camera_zoom_thermal_link">
    <inertial>
      <mass value="0.00001"/>
      <origin rpy="0 0 0" xyz="0 0 0"/>
      <inertia ixx="1.841666666666667e-08" ixy="0" ixz="0" iyy="1.841666666666667e-08" iyz="0" izz="2.016666666666667e-08"/>
    </inertial>
  </link>
  <transmission name="robot_top_ptz_camera_zoom_thermal_trans">
    <type>transmission_interface/SimpleTransmission</type>
    <joint name="robot_top_ptz_camera_zoom_thermal_joint">
      <hardwareInterface>hardware_interface/PositionJointInterface</hardwareInterface>
    </joint>
    <actuator name="robot_top_ptz_camerazoom_thermal_motor">
      <hardwareInterface>hardware_interface/PositionJointInterface</hardwareInterface>
      <mechanicalReduction>1</mechanicalReduction>
    </actuator>
  </transmission>

</robot>
